<?xml version="1.0"?>
<robot name="typeypt">
  <link name="world"/>
  <link name="base_link">
    <visual>
      <geometry>
	<box size="0.95 1.425 0.02"/>
      </geometry>
      <material name="yellow">
        <color rgba="1 1 0.0 0.8"/>
      </material>
      <origin rpy="0 0 0" xyz="0 -0.4 0.0"/>
    </visual>
    <collision>
      <geometry>
	<box size="0.95 1.425 0.02"/>
      </geometry>
      <origin rpy="0 0 0" xyz="0 -0.4 0.0"/>
    </collision>
    <inertial>
      <mass value="1.0"/>
      <origin rpy="0 0 0" xyz="0 -0.4 0.0"/>
      <inertia ixx="0.18" iyy="0.08" izz="0.25" ixy="0" ixz="0" iyz="0"/>
      <dynamics damping="0.05" friction="0.0"/>
    </inertial>

  </link>
  <joint name="fixed" type="fixed">
    <parent link="world"/>
    <child link="base_link"/>
  </joint>
  <link name="torso">
    <visual>
      <geometry>
	<box size="0.53 0.55 0.45"/>
      </geometry>
      <material name="yellow"/>
      <origin rpy="0 0 0" xyz="0 0 0.25"/>
    </visual>
    <collision>
      <geometry>
	<box size="0.53 0.55 0.45"/>
      </geometry>
      <origin rpy="0 0 0" xyz="0 0 0.25"/>
    </collision>
    <inertial>
      <mass value="1.0"/>
      <origin rpy="0 0 0" xyz="0 0 0.25"/>
      <inertia ixx="0.04" iyy="0.04" izz="0.05" ixy="0" ixz="0" iyz="0"/>
      <dynamics damping="0.05" friction="0.0"/>
    </inertial>

  </link>
  <joint name="hip" type="revolute">
    <axis xyz="0 0 1"/>
    <parent link="base_link"/>
    <child link="torso"/>
    <origin rpy="0 0 0" xyz="0.0 0.0 0.12"/>
    <limit effort="30" velocity="1.0" lower="0.0" upper="3.14" />
  </joint>
  <link name="upper_arm">
    <visual>
      <geometry>
        <cylinder length="0.8" radius="0.05"/>
      </geometry>
      <material name="yellow"/>
      <origin rpy="0 0 0" xyz="0  0 0.4"/>
    </visual>
    <collision>
      <geometry>
        <cylinder length="0.8" radius="0.05"/>
      </geometry>
      <origin rpy="0 0 0" xyz="0  0 0.4"/>
    </collision>
    <inertial>
      <mass value="1.0"/>
      <origin rpy="0 0 0" xyz="0  0 0.4"/>
      <inertia ixx="0.16" iyy="0.16" izz="0.32" ixy="0" ixz="0" iyz="0"/>
      <dynamics damping="0.05" friction="0.0"/>
    </inertial>
  </link>
  <joint name="shoulder" type="revolute">
    <origin rpy="0 -1.57 0" xyz="0.2  0.0 0.30"/>
    <parent link="torso"/>
    <child link="upper_arm"/>
    <axis xyz="0 1 0"/>
    <limit effort="30" velocity="1.0" lower="0.52" upper="2.79" />
  </joint>
  <link name="lower_arm">
    <visual>
      <geometry>
        <cylinder length="0.8" radius="0.05"/>
      </geometry>
      <material name="yellow"/>
      <origin rpy="0 0 0" xyz="0 0 0.4"/>
    </visual>
    <collision>
      <geometry>
        <cylinder length="0.8" radius="0.05"/>
      </geometry>
      <origin rpy="0 0 0" xyz="0 0 0.4"/>
    </collision>
    <inertial>
      <mass value="1.0"/>
      <origin rpy="0 0 0" xyz="0 0 0.4"/>
      <inertia ixx="0.16" iyy="0.16" izz="0.32" ixy="0" ixz="0" iyz="0"/>
      <dynamics damping="0.05" friction="0.0"/>
    </inertial>
  </link>
  <joint name="elbow" type="revolute">
    <origin rpy="0 3.36 0" xyz="0.0 0.0 0.8"/>
    <parent link="upper_arm"/>
    <child link="lower_arm"/>
    <axis xyz="0 -1 0"/>
    <limit effort="30" velocity="1.0" lower="0.87" upper="2.44" />
  </joint>
  <link name="hand">
    <visual>
      <geometry>
        <box size="0.05 0.05 0.05"/>
      </geometry>
      <material name="yellow"/>
    </visual>
    <collision>
      <geometry>
        <box size="0.05 0.05 0.05"/>
      </geometry>
      <origin rpy="0 0 0" xyz="0 0 0"/>
    </collision>
    <inertial>
      <mass value="1.0"/>
      <origin rpy="0 0 0" xyz="0 0 0"/>
      <inertia ixx="0.0004" iyy="0.0004" izz="0.0004" ixy="0" ixz="0" iyz="0"/>
      <dynamics damping="0.05" friction="0.0"/>
    </inertial>
  </link>
  <joint name="wrist" type="revolute">
    <axis xyz="1 0 0"/>
    <parent link="lower_arm"/>
    <child link="hand"/>
    <origin rpy="0 0 0" xyz="0.0 0.0 0.805"/>
    <limit effort="30" velocity="1.0" lower="0.0" upper="2.7" />
  </joint>
  <transmission name="tran0">
    <type>transmission_interface/SimpleTransmission</type>
    <joint name="hip">
      <hardwareInterface>PositionJointInterface</hardwareInterface>
    </joint>
    <actuator name="motor0">
      <hardwareInterface>PositionJointInterface</hardwareInterface>
      <mechanicalReduction>1</mechanicalReduction>
    </actuator>
  </transmission>
  <transmission name="tran1">
    <type>transmission_interface/SimpleTransmission</type>
    <joint name="shoulder">
      <hardwareInterface>PositionJointInterface</hardwareInterface>
    </joint>
    <actuator name="motor1">
      <hardwareInterface>PositionJointInterface</hardwareInterface>
      <mechanicalReduction>1</mechanicalReduction>
    </actuator>
  </transmission>
  <transmission name="tran2">
    <type>transmission_interface/SimpleTransmission</type>
    <joint name="elbow">
      <hardwareInterface>PositionJointInterface</hardwareInterface>
    </joint>
    <actuator name="motor2">
      <hardwareInterface>PositionJointInterface</hardwareInterface>
      <mechanicalReduction>1</mechanicalReduction>
    </actuator>
  </transmission>
  <transmission name="tran3">
    <type>transmission_interface/SimpleTransmission</type>
    <joint name="wrist">
      <hardwareInterface>PositionJointInterface</hardwareInterface>
    </joint>
    <actuator name="motor3">
      <hardwareInterface>PositionJointInterface</hardwareInterface>
      <mechanicalReduction>1</mechanicalReduction>
    </actuator>
  </transmission>
  <gazebo>
    <plugin name="control" filename="libgazebo_ros_control.so"/>
  </gazebo>
  <gazebo>
    <plugin name="joint_state_publisher" filename="libgazebo_ros_joint_state_publisher.so">
      <jointName>hip, shoulder, elbow, wrist</jointName>
    </plugin>
  </gazebo>
</robot>
